Workbook

Sheet P&L by FSLI
A1: Profit and loss by financial statement line - January 2026
A2: January closed and signed on business day 6 with ten adjustments posted. Benchmark is FY26 Plan v3 (board approved), locked 2025-12-11.
A3: Variance is favorable-positive. Margins are ROWS under the line they belong to, with the move in points. Nothing on this page is typed: every figure references the tab that owns it.
B5: Line | C5: Actual | D5: Plan | E5: Variance | F5: Var % | G5: Prior month | I5: Owned by
B6: Revenue | C6: ='Revenue and ARR'!C11 | D6: ='Revenue and ARR'!D11 | E6: =C6-D6 | F6: =IF(D6=0,"",E6/ABS(D6)) | G6: ='Revenue and ARR'!G11 | I6: Revenue and ARR
B7: Cost of revenue | C7: ='Gross margin'!C16 | D7: ='Gross margin'!D16 | E7: =D7-C7 | F7: =IF(D7=0,"",E7/ABS(D7)) | G7: ='Gross margin'!G16 | I7: Gross margin
B8: Gross profit | C8: ='Gross margin'!C19 | D8: ='Gross margin'!D19 | E8: =C8-D8 | F8: =IF(D8=0,"",E8/ABS(D8)) | G8: ='Gross margin'!G19 | I8: Gross margin
B9: Gross margin % | C9: =IF(C6=0,"",C8/C6) | D9: =IF(D6=0,"",D8/D6) | E9: =IF(OR(C6=0,D6=0),"",(C8/C6-D8/D6)*100) | G9: =IF(G6=0,"",G8/G6)
A11: OPERATING EXPENSE
B12: Research and development | C12: ='Opex by owner'!E30 | D12: ='Opex by owner'!F30 | E12: =D12-C12 | F12: =IF(D12=0,"",E12/ABS(D12)) | G12: 795164.33 | I12: Opex by owner
B13: Research and development, % of revenue | C13: =IF(C6=0,"",C12/C6) | D13: =IF(D6=0,"",D12/D6) | E13: =IF(OR(C6=0,D6=0),"",(C12/C6-D12/D6)*100) | G13: =IF(G6=0,"",G12/G6)
B14: Sales and marketing | C14: ='Opex by owner'!E31 | D14: ='Opex by owner'!F31 | E14: =D14-C14 | F14: =IF(D14=0,"",E14/ABS(D14)) | G14: 753039.98 | I14: Opex by owner
B15: Sales and marketing, % of revenue | C15: =IF(C6=0,"",C14/C6) | D15: =IF(D6=0,"",D14/D6) | E15: =IF(OR(C6=0,D6=0),"",(C14/C6-D14/D6)*100) | G15: =IF(G6=0,"",G14/G6)
B16: General and administrative | C16: ='Opex by owner'!E32 | D16: ='Opex by owner'!F32 | E16: =D16-C16 | F16: =IF(D16=0,"",E16/ABS(D16)) | G16: 585488.93 | I16: Opex by owner
B17: General and administrative, % of revenue | C17: =IF(C6=0,"",C16/C6) | D17: =IF(D6=0,"",D16/D6) | E17: =IF(OR(C6=0,D6=0),"",(C16/C6-D16/D6)*100) | G17: =IF(G6=0,"",G16/G6)
B18: Total operating expense | C18: =C12+C14+C16 | D18: =D12+D14+D16 | E18: =D18-C18 | F18: =IF(D18=0,"",E18/ABS(D18)) | G18: =G12+G14+G16
B19: Total operating expense, % of revenue | C19: =IF(C6=0,"",C18/C6) | D19: =IF(D6=0,"",D18/D6) | E19: =IF(OR(C6=0,D6=0),"",(C18/C6-D18/D6)*100) | G19: =IF(G6=0,"",G18/G6)
B20: OPERATING RESULT | C20: =C8-C18 | D20: =D8-D18 | E20: =C20-D20 | F20: =IF(D20=0,"",E20/ABS(D20)) | G20: =G8-G18
A22: OTHER INCOME (EXPENSE) AND TAX
A23: 9000 | B23: Interest income | C23: 84180.67 | D23: 70000 | E23: =C23-D23 | F23: =IF(D23=0,"",E23/ABS(D23)) | G23: 87079.01 | I23: Income positive, expense negative - the effect on the net result
A24: 9020 | B24: Foreign exchange gain / (loss) | C24: -553.61 | D24: 0 | E24: =C24-D24 | F24: =IF(D24=0,"",E24/ABS(D24)) | G24: -3198.55 | I24: Income positive, expense negative - the effect on the net result
A25: 9030 | B25: Income tax expense | C25: -4000 | D25: -4000 | E25: =C25-D25 | F25: =IF(D25=0,"",E25/ABS(D25)) | G25: -4000 | I25: Income positive, expense negative - the effect on the net result
B26: Total other income (expense) and tax | C26: =C23+C24+C25 | D26: =D23+D24+D25 | E26: =C26-D26 | G26: =G23+G24+G25
B27: NET RESULT | C27: =C20+C26 | D27: =D20+D26 | E27: =C27-D27 | F27: =IF(D27=0,"",E27/ABS(D27)) | G27: =G20+G26
B28: Net margin % | C28: =IF(C6=0,"",C27/C6) | D28: =IF(D6=0,"",D27/D6) | E28: =IF(OR(C6=0,D6=0),"",(C27/C6-D27/D6)*100) | G28: =IF(G6=0,"",G27/G6)
A31: EBITDA BUILD
A32: EBITDA is earnings before interest, tax, depreciation and amortization. Stock comp is none of those four, so it is added back BELOW the EBITDA line and the result is called what it is. Both measures are on the page: the unadjusted one is what a lender or an acquirer means by the word, and hiding it behind the adjusted number is how an add-back stops being visible.
A33: Account | B33: Line | C33: Actual | D33: Plan | E33: Variance | G33: Prior month | I33: Note
B34: Operating result | C34: =C20 | D34: =D20 | E34: =C34-D34 | G34: =G20
A35: 5070 | B35: Add back COGS - amortization of capitalized software | C35: ='Gross margin'!C13 | D35: ='Gross margin'!D13 | E35: =C35-D35 | G35: 43694.23 | I35: Gross margin tab owns this line
A36: 8080 | B36: Add back G&A - depreciation | C36: 18520 | D36: 18200 | E36: =C36-D36 | G36: 18280
B37: EBITDA | C37: =C34+C35+C36 | D37: =D34+D35+D36 | E37: =C37-D37 | G37: =G34+G35+G36
A38: 6020 | B38: Add back R&D - stock-based compensation | C38: 79000 | D38: 84000 | E38: =C38-D38 | G38: 63333.33
A39: 7020 | B39: Add back S&M - stock-based compensation | C39: 53000 | D39: 56000 | E39: =C39-D39 | G39: 42083.33
A40: 8020 | B40: Add back G&A - stock-based compensation | C40: 66000 | D40: 70000 | E40: =C40-D40 | G40: 52916.67
B41: ADJUSTED EBITDA | C41: =C37+C38+C39+C40 | D41: =D37+D38+D39+D40 | E41: =C41-D41 | G41: =G37+G38+G39+G40
B42: Adjusted EBITDA margin % | C42: =IF(C6=0,"",C41/C6) | D42: =IF(D6=0,"",D41/D6) | E42: =IF(OR(C6=0,D6=0),"",(C41/C6-D41/D6)*100) | G42: =IF(G6=0,"",G41/G6)
A45: RATIO INPUTS - OWNED BY THIS TAB
A46: A day-count needs two things a balance sheet does not carry: the month's revenue and the month's cash operating spend. Both are read off this statement, so a ratio and the statement it describes cannot disagree.
B47: Revenue, January | C47: =C6 | G47: =G6 | I47: P&L, above
...

Sheet Revenue and ARR
A1: Revenue and committed ARR - January 2026
A2: Revenue by stream against the FY26 plan of record, and the ARR waterfall struck from the effective-dated change log.
A3: This tab OWNS revenue. Every other appearance of a revenue figure in this pack is a reference to a cell on this page.
A5: Account | B5: Stream | C5: Actual | D5: Plan | E5: Variance | F5: Var % | G5: Prior month | I5: Note
A6: 4000 | B6: Subscription revenue - platform | C6: 1518870.4 | D6: 1537543 | E6: =C6-D6 | F6: =IF(D6=0,"",E6/ABS(D6)) | G6: 1511709.7
A7: 4010 | B7: Usage revenue - overage | C7: 149825.87 | D7: 209105.85 | E7: =C7-D7 | F7: =IF(D7=0,"",E7/ABS(D7)) | G7: 224476.44
A8: 4020 | B8: Professional services revenue | C8: 96565.35 | D8: 92000 | E8: =C8-D8 | F8: =IF(D8=0,"",E8/ABS(D8)) | G8: 105335.52
A9: 4030 | B9: Other revenue | C9: 9725.87 | D9: 8000 | E9: =C9-D9 | F9: =IF(D9=0,"",E9/ABS(D9)) | G9: 10409.05
A10: 4090 | B10: Contra revenue - credits and refunds | C10: -4634.69 | D10: -2000 | E10: =C10-D10 | F10: =IF(D10=0,"",E10/ABS(D10)) | G10: -18900 | I10: Contra account - reduces revenue
B11: Total revenue | C11: =SUM(C6:C10) | D11: =SUM(D6:D10) | E11: =C11-D11 | F11: =IF(D11=0,"",E11/ABS(D11)) | G11: =SUM(G6:G10)
A14: COMMITTED ARR WATERFALL
A15: Committed recurring subscription only, at contracted price, excluding usage and services - metric MET-001 as ruled. The closing figure is FOOTED from the movements, not stated: a waterfall whose close is typed always ties and tells you nothing.
B16: Movement | C16: USD | I16: Basis
B17: Opening ARR, 31 December 2025 | C17: 17600516 | I17: Closing MRR on the FY2025 waterfall x 12
B18: New logos | C18: 624000 | I18: First contracted MRR, annualized
B19: Expansion | C19: 26497.92 | I19: Seat and tier increases on live customers
B20: Price uplift | C20: 0 | I20: Contracted uplifts taking effect
B21: Contraction | C21: 0 | I21: Downgrades on live customers
B22: Churn | C22: -24570 | I22: Cancellations effective in the month
B23: Closing ARR, 31 January 2026 | C23: =C17+SUM(C18:C22) | I23: Footed from the movements above
B24: Committed ARR per the ARR schedule | C24: 18226444 | I24: MET-001, from arr_schedule_2026-01.csv
B25: Difference | C25: =C23-C24 | I25: Must be nil - the waterfall and the schedule are the same book
A28: THE BOOK BEHIND THE REVENUE
B29: Measure | C29: Value | I29: Definition
B30: Live customers | C30: 121 | I30: Customers with contracted recurring MRR at the period end
B31: Average MRR per customer | C31: 12552.65 | I31: Committed MRR / live customers
B32: Committed MRR | C32: 1518870.4 | I32: Closing ARR / 12
B33: Pages processed | C33: 12835043 | I33: MET-011 denominator - pages processed, not pages invoiced

Sheet Gross margin
A1: Gross margin - January 2026
A2: Cost of revenue by account against plan, and the unit economics behind it.
A3: This tab OWNS cost of revenue by account. Revenue is referenced from the Revenue tab and is not restated here.
A5: Account | B5: Line | C5: Actual | D5: Plan | E5: Variance | F5: Var % | G5: Prior month | I5: Note
A6: 5000 | B6: COGS - model and inference API | C6: 122061.27 | D6: 109559.99 | E6: =D6-C6 | F6: =IF(D6=0,"",E6/ABS(D6)) | G6: 136279.28
A7: 5010 | B7: COGS - cloud hosting and storage | C7: 106453.6 | D7: 107522.5 | E7: =D7-C7 | F7: =IF(D7=0,"",E7/ABS(D7)) | G7: 105352.47
A8: 5020 | B8: COGS - dedicated GPU compute | C8: 39000 | D8: 39000 | E8: =D8-C8 | F8: =IF(D8=0,"",E8/ABS(D8)) | G8: 34500
A9: 5030 | B9: COGS - third-party data and APIs | C9: 24146.8 | D9: 22916.68 | E9: =D9-C9 | F9: =IF(D9=0,"",E9/ABS(D9)) | G9: 22780
A10: 5040 | B10: COGS - support payroll | C10: 36164.22 | D10: 55000 | E10: =D10-C10 | F10: =IF(D10=0,"",E10/ABS(D10)) | G10: 35754
A11: 5050 | B11: COGS - professional services payroll | C11: 56565.25 | D11: 55000 | E11: =D11-C11 | F11: =IF(D11=0,"",E11/ABS(D11)) | G11: 46712.5
A12: 5060 | B12: COGS - delivery contractors | C12: 16442.4 | D12: 15968.1 | E12: =D12-C12 | F12: =IF(D12=0,"",E12/ABS(D12)) | G12: 15810
A13: 5070 | B13: COGS - amortization of capitalized software | C13: 43694.23 | D13: 44500 | E13: =D13-C13 | F13: =IF(D13=0,"",E13/ABS(D13)) | G13: 43694.23 | I13: Non-cash - added back to EBITDA
A14: 5080 | B14: COGS - payment processing fees | C14: 7769 | D14: 11469.6 | E14: =D14-C14 | F14: =IF(D14=0,"",E14/ABS(D14)) | G14: 11469.6
A15: 5090 | B15: COGS - other | C15: 3677.1 | D15: 3584.28 | E15: =D15-C15 | F15: =IF(D15=0,"",E15/ABS(D15)) | G15: 3570
B16: Total cost of revenue | C16: =SUM(C6:C15) | D16: =SUM(D6:D15) | E16: =D16-C16 | F16: =IF(D16=0,"",E16/ABS(D16)) | G16: =SUM(G6:G15)
B18: Revenue | C18: ='Revenue and ARR'!C11 | D18: ='Revenue and ARR'!D11 | E18: =C18-D18 | G18: ='Revenue and ARR'!G11
B19: Gross profit | C19: =C18-C16 | D19: =D18-D16 | E19: =C19-D19 | F19: =IF(D19=0,"",E19/ABS(D19)) | G19: =G18-G16
B20: Gross margin % | C20: =IF(C18=0,"",C19/C18) | D20: =IF(D18=0,"",D19/D18) | E20: =IF(OR(C18=0,D18=0),"",(C19/C18-D19/D18)*100) | G20: =IF(G18=0,"",G19/G18)
A21: The move is in POINTS, which is the number an operator argues about, and is not the percentage variance carried in column F elsewhere on this page.
A24: UNIT ECONOMICS - COST PER PAGE PROCESSED
A25: MET-011 as ruled: accounts 5000, 5010 and 5020 over pages PROCESSED, not pages invoiced. The plan's rate is the FY26 inference curve's starting point, which is what makes a flat month evidence about the distillation program.
A26: Account | B26: Line | C26: Actual USD | D26: Plan USD | F26: Actual per page | G26: Plan per page | I26: Note
A27: 5000 | B27: COGS - model and inference API | C27: =C6 | D27: =D6 | F27: =IF('Revenue and ARR'!C33=0,"",C27/'Revenue and ARR'!C33) | G27: =IF('Revenue and ARR'!C33=0,"",D27/'Revenue and ARR'!C33) | I27: Divided by pages processed on the Revenue tab
A28: 5010 | B28: COGS - cloud hosting and storage | C28: =C7 | D28: =D7 | F28: =IF('Revenue and ARR'!C33=0,"",C28/'Revenue and ARR'!C33) | G28: =IF('Revenue and ARR'!C33=0,"",D28/'Revenue and ARR'!C33) | I28: Divided by pages processed on the Revenue tab
A29: 5020 | B29: COGS - dedicated GPU compute | C29: =C8 | D29: =D8 | F29: =IF('Revenue and ARR'!C33=0,"",C29/'Revenue and ARR'!C33) | G29: =IF('Revenue and ARR'!C33=0,"",D29/'Revenue and ARR'!C33) | I29: Divided by pages processed on the Revenue tab
B30: Blended cost per page | C30: =SUM(C27:C29) | D30: =SUM(D27:D29) | F30: =IF('Revenue and ARR'!C33=0,"",C30/'Revenue and ARR'!C33) | G30: =IF('Revenue and ARR'!C33=0,"",D30/'Revenue and ARR'!C33) | I30: The line the FY26 exit margin depends on

Sheet Opex by owner
A1: Operating expense by cost center owner - January 2026
A2: Every operating dollar against the person who answers for it.
A3: Grain is cost center AND financial statement line. A center may spend across more than one - an Executive salary is G&A while the same center's engineering spend is R&D - and collapsing that is what makes the by-owner cut and the by-FSLI cut disagree while both still foot.
A5: Cost center | B5: Name | C5: Owner | D5: Entity | E5: Actual | F5: Plan | G5: Variance | H5: Var % | J5: Statement line
A6: CC-100 | B6: Executive | C6: Dana Whitfield (CEO) | D6: ARC-US | E6: 26376.74 | F6: 35315.45 | G6: =F6-E6 | H6: =IF(F6=0,"",G6/ABS(F6)) | J6: Research and development
A7: CC-200 | B7: Engineering | C7: Priya Raghavan (VP Engineering) | D7: ARC-US | E7: 380204.76 | F7: 437735.41 | G7: =F7-E7 | H7: =IF(F7=0,"",G7/ABS(F7)) | J7: Research and development
A8: CC-210 | B8: Applied Research | C8: Tomas Lindqvist (Head of Applied Research) | D8: ARC-US | E8: 472399.4 | F8: 177238.06 | G8: =F8-E8 | H8: =IF(F8=0,"",G8/ABS(F8)) | J8: Research and development
A9: CC-220 | B9: Platform & Infrastructure | C9: Marcus Bell (Head of Infrastructure) | D9: ARC-US | E9: 189961.95 | F9: 152935.74 | G9: =F9-E9 | H9: =IF(F9=0,"",G9/ABS(F9)) | J9: Research and development
A10: CC-300 | B10: Product & Design | C10: Elena Duarte (VP Product) | D10: ARC-US | E10: 105341.12 | F10: 122980.01 | G10: =F10-E10 | H10: =IF(F10=0,"",G10/ABS(F10)) | J10: Research and development
A11: CC-500 | B11: Marketing | C11: Naomi Ostrander (VP Marketing) | D11: ARC-US | E11: -215000 | F11: 0 | G11: =F11-E11 | H11: =IF(F11=0,"",G11/ABS(F11)) | J11: Research and development
A12: CC-700 | B12: Finance | C12: Jonathan Reyes (VP Finance) | D12: ARC-US | E12: 24615.9 | F12: 0 | G12: =F12-E12 | H12: =IF(F12=0,"",G12/ABS(F12)) | J12: Research and development
A13: CC-400 | B13: Sales - Enterprise | C13: Grant Mwangi (VP Sales) | D13: ARC-US | E13: 283759.42 | F13: 224831.77 | G13: =F13-E13 | H13: =IF(F13=0,"",G13/ABS(F13)) | J13: Sales and marketing
A14: CC-410 | B14: Sales - Mid-market | C14: Grant Mwangi (VP Sales) | D14: ARC-US | E14: 64715.64 | F14: 111398.3 | G14: =F14-E14 | H14: =IF(F14=0,"",G14/ABS(F14)) | J14: Sales and marketing
A15: CC-420 | B15: Sales Engineering | C15: Ruth Oyelaran (Dir. Sales Engineering) | D15: ARC-US | E15: 58907.68 | F15: 118789.15 | G15: =F15-E15 | H15: =IF(F15=0,"",G15/ABS(F15)) | J15: Sales and marketing
A16: CC-430 | B16: Revenue Operations | C16: Kevin Sandoval (Dir. RevOps) | D16: ARC-US | E16: 85376.06 | F16: 76479.22 | G16: =F16-E16 | H16: =IF(F16=0,"",G16/ABS(F16)) | J16: Sales and marketing
A17: CC-440 | B17: Sales - EMEA | C17: Isabelle Rochet (Dir. EMEA) | D17: ARC-UK | E17: 43802.93 | F17: 88536.23 | G17: =F17-E17 | H17: =IF(F17=0,"",G17/ABS(F17)) | J17: Sales and marketing
... A25: CC-730 | B25: IT & Security | C25: Marcus Bell (Head of Infrastructure) | D25: ARC-US | E25: 83289.58 | F25: 60857.15 | G25: =F25-E25 | H25: =IF(F25=0,"",G25/ABS(F25)) | J25: General and administrative
A27: BY STATEMENT LINE
A28: These three subtotals are what the P&L by FSLI points at. The two cuts are equal by construction at this grain, and the verifier proves it rather than assuming it.
B29: Statement line | E29: Actual | F29: Plan | G29: Variance | H29: Var %
B30: Research and development | E30: =E6+E7+E8+E9+E10+E11+E12 | F30: =F6+F7+F8+F9+F10+F11+F12 | G30: =F30-E30 | H30: =IF(F30=0,"",G30/ABS(F30))
B31: Sales and marketing | E31: =E13+E14+E15+E16+E17+E18+E19+E20 | F31: =F13+F14+F15+F16+F17+F18+F19+F20 | G31: =F31-E31 | H31: =IF(F31=0,"",G31/ABS(F31))
B32: General and administrative | E32: =E21+E22+E23+E24+E25 | F32: =F21+F22+F23+F24+F25 | G32: =F32-E32 | H32: =IF(F32=0,"",G32/ABS(F32))
B33: Total operating expense | E33: =SUM(E30:E32) | F33: =SUM(F30:F32) | G33: =F33-E33 | H33: =IF(F33=0,"",G33/ABS(F33))

Sheet Balance sheet
A1: Balance sheet - 31 January 2026, with 31 December 2025
A2: Classified current and non-current, so a ratio can be built over a subtotal that already exists on the page.
A3: A hand-listed SUM of account rows breaks the first time somebody adds an account. Built over a subtotal, it cannot.
A5: Account | B5: Line | C5: 31 Jan 2026 | D5: 31 Dec 2025 | E5: Movement | G5: Class | H5: Classification basis
A6: Current assets
A7: 1000 | B7: Cash - operating (Mercury) | C7: 18190127 | D7: 19274836 | E7: =C7-D7 | G7: Current | H7: Settles or converts within twelve months
A8: 1010 | B8: Cash - payroll clearing | C8: 0.03 | D8: 0.03 | E8: =C8-D8 | G8: Current | H8: Settles or converts within twelve months
A9: 1020 | B9: Treasury - money market | C9: 5453612.7 | D9: 5369432.1 | E9: =C9-D9 | G9: Current | H9: Settles or converts within twelve months
A10: 1030 | B10: Stripe clearing account | C10: 142000 | D10: 216793.6 | E10: =C10-D10 | G10: Current | H10: Settles or converts within twelve months
A11: 1100 | B11: Accounts receivable - trade | C11: 4890193.4 | D11: 3307580.7 | E11: =C11-D11 | G11: Current | H11: Settles or converts within twelve months
A12: 1150 | B12: Allowance for credit losses | C12: -117280 | D12: -112560 | E12: =C12-D12 | G12: Current | H12: Settles or converts within twelve months
A13: 1200 | B13: Unbilled receivable (contract asset) | C13: 425978.58 | D13: 310000 | E13: =C13-D13 | G13: Current | H13: Settles or converts within twelve months
A14: 1300 | B14: Prepaid expenses - other | C14: 221558.5 | D14: 185000 | E14: =C14-D14 | G14: Current | H14: Settles or converts within twelve months
A15: 1310 | B15: Prepaid software subscriptions | C15: 543083.46 | D15: 420000.12 | E15: =C15-D15 | G15: Current | H15: Settles or converts within twelve months
A16: 1320 | B16: Prepaid insurance | C16: 80333.29 | D16: 95999.96 | E16: =C16-D16 | G16: Current | H16: Settles or converts within twelve months
A17: 1330 | B17: Prepaid cloud commitments | C17: 240000 | D17: 240000 | E17: =C17-D17 | G17: Current | H17: Settles or converts within twelve months
A18: 1400 | B18: Deferred commissions - current | C18: 228184.23 | D18: 272341.91 | E18: =C18-D18 | G18: Current | H18: Settles or converts within twelve months
... A20: 1900 | B20: Intercompany receivable - ARC-UK | C20: 1190990.1 | D20: 1087487.6 | E20: =C20-D20 | G20: Current | H20: Settles or converts within twelve months
B21: Total current assets | C21: =SUM(C7:C20) | D21: =SUM(D7:D20) | E21: =C21-D21
A23: Non-current assets
A24: 1410 | B24: Deferred commissions - non-current | C24: 510000 | D24: 510000 | E24: =C24-D24 | G24: Non-current | H24: Deferred commissions amortizing beyond twelve months
A25: 1600 | B25: Computer equipment | C25: 1016955.8 | D25: 1000524.8 | E25: =C25-D25 | G25: Non-current | H25: Property and equipment
A26: 1610 | B26: Leasehold improvements | C26: 310000 | D26: 310000 | E26: =C26-D26 | G26: Non-current | H26: Property and equipment
A27: 1620 | B27: Capitalized internal-use software | C27: 2003237.4 | D27: 1944377.2 | E27: =C27-D27 | G27: Non-current | H27: Capitalized internal-use software
A28: 1650 | B28: Accumulated depreciation | C28: -620040 | D28: -601520 | E28: =C28-D28 | G28: Non-current | H28: Contra - property and equipment
A29: 1660 | B29: Accumulated amortization - IUS | C29: -833653.88 | D29: -789959.65 | E29: =C29-D29 | G29: Non-current | H29: Contra - capitalized software
A30: 1700 | B30: Operating lease right-of-use asset | C30: 1080500 | D30: 1122000 | E30: =C30-D30 | G30: Non-current | H30: Operating lease right-of-use asset
A31: 1800 | B31: Security deposits | C31: 180000 | D31: 180000 | E31: =C31-D31 | G31: Non-current | H31: Security deposits
B32: Total non-current assets | C32: =SUM(C24:C31) | D32: =SUM(D24:D31) | E32: =C32-D32
A34: Current liabilities
A35: 2000 | B35: Accounts payable | C35: -2906037.2 | D35: -2679158.9 | E35: =C35-D35 | G35: Current | H35: Settles or converts within twelve months
A36: 2010 | B36: Accrued expenses | C36: -359161.67 | D36: -298911.75 | E36: =C36-D36 | G36: Current | H36: Settles or converts within twelve months
A37: 2020 | B37: Accrued compensation | C37: -193204.71 | D37: -189522.4 | E37: =C37-D37 | G37: Current | H37: Settles or converts within twelve months
A38: 2030 | B38: Accrued bonus | C38: -1216170.4 | D38: -1116656.7 | E38: =C38-D38 | G38: Current | H38: Settles or converts within twelve months
A39: 2040 | B39: Accrued commissions | C39: -77334.23 | D39: -22041.91 | E39: =C39-D39 | G39: Current | H39: Settles or converts within twelve months
A40: 2050 | B40: Accrued PTO | C40: -499990 | D40: -492980 | E40: =C40-D40 | G40: Current | H40: Settles or converts within twelve months
A41: 2070 | B41: Sales tax payable | C41: -62000 | D41: -62000 | E41: =C41-D41 | G41: Current | H41: Settles or converts within twelve months
A42: 2080 | B42: Payroll liabilities | C42: -110402.69 | D42: -108298.51 | E42: =C42-D42 | G42: Current | H42: Settles or converts within twelve months
A43: 2100 | B43: Deferred revenue - current | C43: -7407107 | D43: -6296719.1 | E43: =C43-D43 | G43: Current | H43: Settles or converts within twelve months
A44: 2200 | B44: Operating lease liability - current | C44: -130000 | D44: -160000 | E44: =C44-D44 | G44: Current | H44: Settles or converts within twelve months
...

Sheet Cash
A1: Cash - January 2026
A2: The indirect walk, built as a partition of every non-cash account.
A3: Double entry says the cash movement equals minus the movement of everything else. Enumerating every account rather than the items somebody remembered is what makes the walk reach the ledger with nothing left over - and what makes a forgotten account announce itself instead of disappearing into a plug.
B5: Line | C5: January 2026 | D5: December 2025 | F5: Note
B6: Net result | C6: -1035674.7 | D6: -676704.15 | F6: Ties to the P&L's net result - a verified check
B7: Add back stock comp | C7: 198000 | D7: 158333.33 | F7: The credit is to APIC, which is why it is not an equity raise below
B8: Add back depreciation and amortization | C8: 62214.23 | D8: 61974.23 | F8: Taken from the movement on accumulated depreciation - the add-back and that movement are the SAME entry and cannot be counted twice
B9: Add back credit loss provision | C9: 4720 | D9: 6040 | F9: Non-cash; the allowance sits against receivables
B10: Working capital and all other non-cash movement | C10: -229289.99 | D10: 131953.93 | F10: Every remaining non-cash account, enumerated - not a list
B11: Cash from operations | C11: =SUM(C6:C10) | D11: =SUM(D6:D10) | F11: Footed from the lines above
B12: Investing - capital expenditure and deposits | C12: -75291.27 | D12: -78313.24 | F12: Movement on gross fixed assets, capitalized software and security deposits
B13: Financing | C13: 0 | D13: 0 | F13: Equity movement LESS the result and the stock comp credit - what is left is a raise, and nil here means there was not one
B14: NET CASH MOVEMENT | C14: =C11+C12+C13 | D14: =D11+D12+D13
B16: Opening cash | C16: 24861062 | D16: 25257778
B17: Closing cash, per the walk | C17: =C16+C14 | D17: =D16+D14
B18: Closing cash, per the balance sheet | C18: ='Balance sheet'!C7+'Balance sheet'!C8+'Balance sheet'!C9+'Balance sheet'!C10 | D18: ='Balance sheet'!D7+'Balance sheet'!D8+'Balance sheet'!D9+'Balance sheet'!D10 | F18: The ledger cash accounts, referenced - not restated
B19: Difference - must be nil | C19: =C17-C18 | D19: =D17-D18 | F19: A partition cannot leave a residual. If this is not nil, an account is in no bucket.
A22: BURN AND RUNWAY
A23: Runway is the one measure a single month cannot carry, so it runs on a three-month window. The condition is IN THE FORMULA, not in a footnote: only months that CONSUMED cash count, because averaging in a month that raised money flatters the answer.
B24: Line | C24: January 2026 | D24: December 2025 | F24: Note
B25: Free cash flow, 2025-10 | C25: -381547 | F25: Cash from operations plus investing
B26: Free cash flow, 2025-11 | C26: -552080.77 | F26: Cash from operations plus investing
B27: Free cash flow, 2025-12 | C27: -396715.9 | F27: Cash from operations plus investing
B28: Free cash flow, 2026-01 | C28: -1075321.8 | F28: Cash from operations plus investing
B29: Average monthly burn - months that consumed cash only | C29: =IFERROR(-AVERAGEIF(C26:C28,"<0"),0) | D29: =IFERROR(-AVERAGEIF(C25:C27,"<0"),0) | F29: Two overlapping three-month windows, so the prior-month figure is a formula too and the overlap is visible
B30: Runway, months | C30: =IFERROR(C18/C29,"") | D30: =IFERROR(D18/D29,"") | F30: Closing cash over average net burn - MET-010

Sheet SaaS metrics
A1: SaaS metrics - January 2026
A2: The metric registry, computed at the version it was ruled, and an explicit statement of what is NOT computable and why.
A3: A metric with no ruled definition is left blank and named. Filling it with a plausible number is how a definition gets decided by whoever built the spreadsheet.
A5: Metric | B5: Name | C5: Value | D5: Status | E5: Owner | G5: Definition, or why it is blank
A6: MET-001 | B6: Committed recurring ARR | C6: ='Revenue and ARR'!C23 | D6: Ruled v1.0 | E6: VP Finance | G6: Contracted recurring subscription MRR x 12, at contracted price
A7: MET-002 | B7: Total revenue | C7: ='P&L by FSLI'!C6 | D7: Ruled v1.0 | E7: VP Finance | G7: Sum of accounts 4000-4090
A8: MET-003 | B8: Gross margin % | C8: ='P&L by FSLI'!C8/'P&L by FSLI'!C6 | D8: Ruled v1.0 | E8: VP Finance | G8: (Total revenue - cost of revenue) / total revenue
A9: MET-004 | B9: Adjusted EBITDA | C9: ='P&L by FSLI'!C41 | D9: Ruled v1.0 | E9: VP Finance | G9: Operating result + SBC + depreciation and amortization
A10: MET-005 | B10: Net revenue retention | D10: UNRESOLVED | E10: VP Customer Success | G10: Computable from customer_mrr_changes.csv once the cohort definition is ruled
A11: MET-006 | B11: Gross revenue retention | D11: UNRESOLVED | E11: VP Customer Success
A12: MET-007 | B12: Customer acquisition cost | D12: Ruled v1.0 | E12: VP Marketing | G12: S&M in period / new logos in period - not computed in this pack: needs a period comparison this single-month pack does not carry.
A13: MET-008 | B13: Magic number | D13: Ruled v1.0 | E13: VP Finance | G13: 4 x (revenue QoQ delta) / prior quarter S&M - not computed in this pack: needs a period comparison this single-month pack does not carry.
A14: MET-009 | B14: Burn multiple | D14: Ruled v1.0 | E14: VP Finance | G14: Net cash burn / net new ARR - not computed in this pack: needs a period comparison this single-month pack does not carry.
A15: MET-010 | B15: Runway, months | C15: ='Cash'!C30 | D15: Ruled v1.0 | E15: VP Finance | G15: Closing cash / trailing three-month average net cash burn
A16: MET-011 | B16: Cost per page processed | C16: ='Gross margin'!F30 | D16: Ruled v1.0 | E16: Head of Infrastructure | G16: Accounts 5000+5010+5020 / pages processed
A17: MET-012 | B17: Revenue per head | C17: 180428.49 | D17: Ruled v1.0 | E17: VP Finance | G17: Trailing twelve month revenue / closing headcount
A18: MET-013 | B18: DSO | C18: ='Balance sheet'!C70 | D18: Ruled v1.0 | E18: VP Finance | G18: Closing AR / revenue x days in period
A19: MET-014 | B19: Rule of 40 | D19: Ruled v1.0 | E19: VP Finance | G19: Revenue growth % + adjusted EBITDA margin % - not computed in this pack: needs a period comparison this single-month pack does not carry.
A20: MET-015 | B20: Overage capture rate | D20: UNRESOLVED | E20: Dir. RevOps | G20: Requires a ruling on whether uninvoiced overage counts as captured
A22: Revenue per head uses trailing twelve month revenue over closing headcount (98 active). It is the one figure on this tab taken from outside the close month, and it is typed rather than referenced because no tab in this pack owns a trailing twelve month series.

Sheet LBE Q1 M1
A1: Arcline AI, Inc. - Q1 2026 latest best estimate
A2: LBE_Q1_2026_M1, built on information to the January close and stamped 2026-02-06. Draft for ratification - the LBE is never a variance benchmark.
A3: Benchmark is FY26 Plan v3 (board approved), locked 2025-12-11. Costs are shown negative; every Variance cell is that line's effect on the operating result, so the column adds down the page. LBE = Fcst + Variance on every row.
A4: All change suggestions from the January flux analysis are ratified in this build: 43 of 63 classified lines move the forecast, 16 are absorbed by the quarter and move nothing.
B6: Owner | C6: Fcst Q1 | D6: Variance | E6: LBE Q1 | F6: Var % | H6: Comments | I6: Traces to
A7: REVENUE
A8: 4000 Subscription revenue - platform | C8: 4825129.1 | D8: -56018.01 | E8: =C8+D8 | F8: =IF(C8=0,"",D8/ABS(C8)) | H8: January sticks -56,018. Net new MRR of USD 52,160 against a planned USD 70,833: 4 new logos (Tidewater Freight, Drayton Energy, Bellwether Group, Marlowe Foods, USD.... | I8: Subscription revenue - platform / (customer billing): -56,018 (sticks, Run-rate)
A9: 4010 Usage revenue - overage | C9: 656217.56 | D9: -84144.63 | E9: =C9+D9 | F9: =IF(C9=0,"",D9/ABS(C9)) | H9: -84,145 materializes on the open months. Two causes. | I9: Usage revenue - overage / (customer billing): -84,145 (materializes, Timing)
A10: 4020 Professional services revenue | C10: 283200 | D10: 0 | E10: =C10+D10 | F10: =IF(C10=0,"",D10/ABS(C10))
A11: 4030 Other revenue | C11: 24000 | D11: 5177.61 | E11: =C11+D11 | F11: =IF(C11=0,"",D11/ABS(C11)) | H11: January sticks +5,178. Training and certification billed USD 9,726 against a plan run rate of USD 8,000 set below the actual December level of USD 10,409. | I11: Other revenue / (customer billing): +5,178 (sticks, Run-rate)
A12: 4090 Contra revenue - credits and refunds | C12: -6000 | D12: -13141.35 | E12: =C12+D12 | F12: =IF(C12=0,"",D12/ABS(C12)) | H12: January sticks -13,141. SLA credits of USD 4,635 against a USD 2,000 allowance struck at 0.1% of planned revenue. | I12: Contra revenue - credits and refunds / (customer billing): -13,141 (sticks, Run-rate)
A13: Total revenue | C13: =SUM(C8:C12) | D13: =SUM(D8:D12) | E13: =C13+D13 | F13: =IF(C13=0,"",D13/ABS(C13))
A14: COST OF REVENUE
A15: 5000 COGS - model and inference API | C15: -338704.19 | D15: -33565 | E15: =C15+D15 | F15: =IF(C15=0,"",D15/ABS(C15)) | H15: January sticks -33,565. Rate USD 9,113 of the USD 12,501; volume USD 3,388. | I15: COGS - model and inference API / Anthropic PBC / OpenAI, L.L.C. / Mistral AI SAS / Together Computer, Inc. (blended): -33,565 (sticks, Rate-driven)
A16: 5010 COGS - cloud hosting and storage | C16: -325458.01 | D16: 3206.7 | E16: =C16+D16 | F16: =IF(C16=0,"",D16/ABS(C16)) | H16: January sticks +3,207. Volume cost USD 3,325; unit rate saved USD 4,394. | I16: COGS - cloud hosting and storage / Amazon Web Services / Snowflake / GCP / Pinecone / Cloudflare: +3,207 (sticks, Rate-driven)
A17: 5020 COGS - dedicated GPU compute | C17: -117000 | D17: 0 | E17: =C17+D17 | F17: =IF(C17=0,"",D17/ABS(C17))
A18: 5030 COGS - third-party data and APIs | C18: -69163.36 | D18: -3690.36 | E18: =C18+D18 | F18: =IF(C18=0,"",D18/ABS(C18)) | H18: January sticks -3,690. USD 24,147 against a plan built off the December run rate at 0.6% monthly growth. | I18: COGS - third-party data and APIs / Halstead Data Partners / Scale AI / Dun & Bradstreet / Clearbit: -3,690 (sticks, Run-rate)
A19: 5040 COGS - support payroll | C19: -165000 | D19: 61165.78 | E19: =C19+D19 | F19: =IF(C19=0,"",D19/ABS(C19)) | H19: January sticks +61,166. Heads USD 11,000, rate USD 6,271. | I19: COGS - support payroll / (no vendor - internal entry): +61,166 (sticks, Run-rate)
A20: 5050 COGS - professional services payroll | C20: -165000 | D20: -7614.25 | E20: =C20+D20 | F20: =IF(C20=0,"",D20/ABS(C20)) | H20: January sticks -7,614. Five delivery heads at USD 696,294 loaded, USD 58,025 a month against a plan of USD 55,000. | I20: COGS - professional services payroll / (no vendor - internal entry): -7,614 (sticks, Run-rate)
A21: 5060 COGS - delivery contractors | C21: -48384.94 | D21: -1422.9 | E21: =C21+D21 | F21: =IF(C21=0,"",D21/ABS(C21)) | H21: January sticks -1,423. Contractor days billed USD 16,442 against a December run rate of USD 15,810 grown at 1.0%. | I21: COGS - delivery contractors / Miscellaneous suppliers (under $5k): -1,423 (sticks, Run-rate)
A22: 5070 COGS - amortization of capitalized software | C22: -136200 | D22: 5118 | E22: =C22+D22 | F22: =IF(C22=0,"",D22/ABS(C22)) | H22: January sticks +5,118. The charge is USD 43,694.23, identical to December and to the trailing 3-month average to the cent, which is exactly right: the register placed.... | I22: COGS - amortization of capitalized software / (no vendor - internal entry): +5,118 (sticks, Run-rate)
A23: 5080 COGS - payment processing fees | C23: -34408.8 | D23: 7517.4 | E23: =C23+D23 | F23: =IF(C23=0,"",D23/ABS(C23)) | H23: January sticks +7,517. The effective rate did not move at all: USD 11,966.55 of fees on USD 509,215.00 of card-collected billings settled through Stripe is 2.350000%,.... | I23: COGS - payment processing fees / Stripe, Inc.: +7,517 (sticks, Volume-driven)
A24: 5090 COGS - other | C24: -10795.91 | D24: -278.46 | E24: =C24+D24 | F24: =IF(C24=0,"",D24/ABS(C24)) | H24: January sticks -278. Localization at USD 3,677 against a December run rate of USD 3,570 grown at 0.4%. | I24: COGS - other / Unbabel Ltda: -278 (sticks, Run-rate)
A25: Total cost of revenue | C25: =SUM(C15:C24) | D25: =SUM(D15:D24) | E25: =C25+D25 | F25: =IF(C25=0,"",D25/ABS(C25))
A26: GROSS PROFIT | C26: =C13+C25 | D26: =D13+D25 | E26: =C26+D26 | F26: =IF(C26=0,"",D26/ABS(C26))
A27: Gross margin % | C27: =IF(C13=0,"",C26/C13) | E27: =IF(E13=0,"",E26/E13) | F27: =IF(OR(C13=0,E13=0),"",(E26/E13-C26/C13)*100) | H27: Move in points, not the percentage variance in the column above.
A28: OPERATING EXPENSE, BY COST CENTER OWNER
A29: CC-100 Executive | B29: Dana Whitfield (CEO) | C29: -791293.2 | D29: -28499.13 | E29: =C29+D29 | F29: =IF(C29=0,"",D29/ABS(C29)) | H29: January sticks +13,991; -42,490 materializes on the open months. -100,251 in Q1 if the accrual holds at 100% of target; each 10 points of company multiplier is roughly USD 10.4k a quarter in G&A alone. | I29: G&A - salaries and wages / (no vendor - internal entry): -36,434 (materializes, Rate-driven) | R&D - salaries and wages / (no vendor - internal entry): +11,745 (sticks, Rate-driven) | G&A - payroll taxes and benefits / (no vendor - internal entry): -6,056 (materializes, Rate-driven) | R&D - payroll taxes and benefits / (no vendor - internal entry): +2,246 (sticks, Rate-driven)
A30: CC-200 Engineering | B30: Priya Raghavan (VP Engineering) | C30: -1351685.3 | D30: 56867.64 | E30: =C30+D30 | F30: =IF(C30=0,"",D30/ABS(C30)) | H30: January sticks +148,153; -74,064 materializes on the open months. +64,900 a month while the roster holds; +129,800 Feb+Mar. | I30: R&D - salaries and wages / (no vendor - internal entry): +132,807 (sticks, Rate-driven) | R&D - capitalized software labor (contra) / (no vendor - internal entry): -74,064 (materializes, One-time) | R&D - payroll taxes and benefits / (no vendor - internal entry): +25,626 (sticks, Rate-driven) | R&D - contractors / Thoughtbolt Engineering LLC: -17,221 (absorbed, Volume-driven) | R&D - software and developer tools / GitHub, Inc.: -4,050 (sticks, Rate-driven) | R&D - software and developer tools / LaunchDarkly, Inc.: -2,388 (sticks, Rate-driven) | R&D - software and developer tools / Sentry (Functional Software): -1,765 (sticks, Rate-driven) | R&D - software and developer tools / JetBrains s.r.o.: -1,090 (sticks, Rate-driven) | R&D - software and developer tools / Linear Orbit, Inc.: -986 (sticks, Rate-driven)
A31: CC-210 Applied Research | B31: Tomas Lindqvist (Head of Applied Research) | C31: -547294.27 | D31: -221052.26 | E31: =C31+D31 | F31: =IF(C31=0,"",D31/ABS(C31)) | H31: January sticks -221,052. -177,000 Feb+Mar if the reservation recurs; -88,500 Jan already booked. | I31: R&D - research compute / CoreWeave, Inc.: -265,500 (sticks, Run-rate) | R&D - salaries and wages / (no vendor - internal entry): +59,212 (sticks, Rate-driven) | R&D - research compute / Weights & Biases, Inc.: -16,096 (sticks, Rate-driven) | R&D - payroll taxes and benefits / (no vendor - internal entry): +11,273 (sticks, Rate-driven) | R&D - research compute / Hugging Face, Inc.: -9,942 (sticks, Rate-driven)
A32: CC-220 Platform & Infrastructure | B32: Marcus Bell (Head of Infrastructure) | C32: -472251.02 | D32: 9899.12 | E32: =C32+D32 | F32: =IF(C32=0,"",D32/ABS(C32)) | H32: January sticks +59,315. +64,900 a month while the roster holds; +129,800 Feb+Mar. | I32: R&D - salaries and wages / (no vendor - internal entry): +51,093 (sticks, Rate-driven) | R&D - software and developer tools / Datadog, Inc.: -49,416 (absorbed, One-time) | R&D - payroll taxes and benefits / (no vendor - internal entry): +9,728 (sticks, Rate-driven) | R&D - software and developer tools / PagerDuty, Inc.: -1,506 (sticks, Rate-driven)
A33: CC-300 Product & Design | B33: Elena Duarte (VP Product) | C33: -379750.58 | D33: 46139.46 | E33: =C33+D33 | F33: =IF(C33=0,"",D33/ABS(C33)) | H33: January sticks +46,139. +64,900 a month while the roster holds; +129,800 Feb+Mar. | I33: R&D - salaries and wages / (no vendor - internal entry): +41,173 (sticks, Rate-driven) | R&D - payroll taxes and benefits / (no vendor - internal entry): +7,822 (sticks, Rate-driven) | R&D - software and developer tools / Figma, Inc.: -1,973 (sticks, Rate-driven) | R&D - software and developer tools / Maze Design Ltd: -883 (sticks, Rate-driven)
A34: CC-400 Sales - Enterprise | B34: Grant Mwangi (VP Sales) | C34: -686431.83 | D34: 71083.77 | E34: =C34+D34 | F34: =IF(C34=0,"",D34/ABS(C34)) | H34: +71,084 materializes on the open months. Q1 favorable approx USD 255k. | I34: S&M - salaries and wages / (no vendor - internal entry): +62,816 (materializes, Run-rate) | S&M - payroll taxes and benefits / (no vendor - internal entry): +10,668 (materializes, Run-rate) | S&M - travel and entertainment / Navan, Inc.: -2,400 (materializes, Run-rate)
A35: CC-410 Sales - Mid-market | B35: Grant Mwangi (VP Sales) | C35: -340109.15 | D35: 38495.66 | E35: =C35+D35 | F35: =IF(C35=0,"",D35/ABS(C35)) | H35: +38,496 materializes on the open months. Q1 favorable approx USD 255k. | I35: S&M - salaries and wages / (no vendor - internal entry): +32,986 (materializes, Run-rate) | S&M - payroll taxes and benefits / (no vendor - internal entry): +5,509 (materializes, Run-rate)
A36: CC-420 Sales Engineering | B36: Ruth Oyelaran (Dir. Sales Engineering) | C36: -362674.08 | D36: 41327 | E36: =C36+D36 | F36: =IF(C36=0,"",D36/ABS(C36)) | H36: +41,327 materializes on the open months. Q1 favorable approx USD 255k. | I36: S&M - salaries and wages / (no vendor - internal entry): +35,452 (materializes, Run-rate) | S&M - payroll taxes and benefits / (no vendor - internal entry): +5,875 (materializes, Run-rate)
A37: CC-430 Revenue Operations | B37: Kevin Sandoval (Dir. RevOps) | C37: -233498.01 | D37: 8492.23 | E37: =C37+D37 | F37: =IF(C37=0,"",D37/ABS(C37)) | H37: +8,492 materializes on the open months. Q1 favorable approx USD 255k. | I37: S&M - salaries and wages / (no vendor - internal entry): +23,210 (materializes, Run-rate) | S&M - software and tools / Gong.io, Inc.: -18,500 (materializes, Rate-driven) | S&M - payroll taxes and benefits / (no vendor - internal entry): +3,782 (materializes, Run-rate)
A38: CC-440 Sales - EMEA | B38: Isabelle Rochet (Dir. EMEA) | C38: -270309.17 | D38: 30486 | E38: =C38+D38 | F38: =IF(C38=0,"",D38/ABS(C38)) | H38: +30,486 materializes on the open months. Q1 favorable approx USD 255k. | I38: S&M - salaries and wages / (no vendor - internal entry): +24,919 (materializes, Run-rate) | S&M - payroll taxes and benefits / (no vendor - internal entry): +5,567 (materializes, Run-rate)
A39: CC-500 Marketing | B39: Naomi Ostrander (VP Marketing) | C39: -440833.78 | D39: 33646.29 | E39: =C39+D39 | F39: =IF(C39=0,"",D39/ABS(C39)) | H39: +33,646 materializes on the open months. Q1 favorable approx USD 255k. | I39: S&M - salaries and wages / (no vendor - internal entry): +40,838 (materializes, Run-rate) | S&M - demand generation and paid media / All media vendors: -14,000 (materializes, Run-rate) | S&M - payroll taxes and benefits / (no vendor - internal entry): +6,808 (materializes, Run-rate)
A40: CC-600 Customer Success | B40: Hana Kobayashi (VP CS) | C40: -357441.64 | D40: 40569.06 | E40: =C40+D40 | F40: =IF(C40=0,"",D40/ABS(C40)) | H40: +40,569 materializes on the open months. Q1 favorable approx USD 255k. | I40: S&M - salaries and wages / (no vendor - internal entry): +34,779 (materializes, Run-rate) | S&M - payroll taxes and benefits / (no vendor - internal entry): +5,790 (materializes, Run-rate)
... A44: CC-730 IT & Security | B44: Marcus Bell (Head of Infrastructure) | C44: -188277.75 | D44: -13279.62 | E44: =C44+D44 | F44: =IF(C44=0,"",D44/ABS(C44)) | H44: -13,280 materializes on the open months. -100,251 in Q1 if the accrual holds at 100% of target; each 10 points of company multiplier is roughly USD 10.4k a quarter in G&A alone. | I44: G&A - salaries and wages / (no vendor - internal entry): -11,423 (materializes, Rate-driven) | G&A - payroll taxes and benefits / (no vendor - internal entry): -1,857 (materializes, Rate-driven)
...

Sheet Exceptions
A1: What the close found, and what it left open
A2: January closed with ten adjustments posted, six items carried and one finding raised after sign-off.
A3: A pack that reports the result and not the book that produced it is the format precedent this one is trying not to repeat.
A5: CLOSE CHECKLIST
A6: Step | B6: Task | C6: Status | D6: Owner | F6: Exception
A7: CL-11 | B7: AP - reverse prior period accruals | C7: Complete | D7: S. Patel | F7: One 2025-12 accrual was left standing; reversed on ADJ-2026-01-001
A8: CL-16 | B8: Payroll - commission accrual | C8: Complete | D8: K. Sandoval | F8: Accelerators quantified and carried as an open item; no January P&L effect
A9: CL-18 | B9: Cost of revenue - infrastructure accruals | C9: Complete | D9: S. Patel | F9: AWS accrual restored (ADJ-002); training capacity reclassified (ADJ-003)
A10: CL-19 | B10: Prepaid schedule | C10: Complete | D10: S. Patel | F10: Gong release stepped to the renewed rate (ADJ-009); franchise tax spread (ADJ-010)
A11: CL-21 | B11: Capitalised software - stage review | C11: Complete | D11: M. Halloran | F11: Stage review performed; two findings carried to the open items list
A12: CL-26 | B12: FX revaluation | C12: Complete | D12: S. Patel | F12: Intercompany exposure quantified and carried; revaluation policy amended
A13: CL-27 | B13: Bank reconciliation | C13: Complete | D13: T. Byrne | F13: Difference identified against bank advice MERC-FEB-01 and written off
A14: CL-28 | B14: Sales and indirect tax | C14: Complete | D14: Armanino LLP | F14: Nexus study commissioned; exposure quantified and disclosed
A15: CL-30 | B15: Balance sheet reconciliations | C15: Complete | D15: M. Halloran | F15: All 31 balance sheet accounts reconciled
A16: CL-31 | B16: Flux analysis | C16: Complete | D16: J. Reyes | F16: Flux analysis complete; see 03-actuals/FY2026/
A17: CL-33 | B17: Subsequent events review | C17: Complete | D17: M. Halloran | F17: Post-close inbox cleared; four invoices accrued, one credit memo carried
A19: 34 of 34 steps complete. Only steps carrying an exception are listed above.
A21: OPEN ITEMS CARRIED OUT OF THE CLOSE
A22: Six items, carried knowingly and accepted at sign-off. Each names what it is, who owns it, and what
A23: happens if it is not resolved.
A24: Ref | B24: Item | C24: Owner | D24: Due | F24: If not resolved
A25: OI-01 | B25: Sales tax nexus study. No sales tax has been charged on any invoice since inception. NY, TX, WA, AZ, UT, OH and PA all treat SaaS as taxable and the company invoices customers in all of them. Exposure quantified during the close. | C25: VP Finance with Avalara | D25: 2026-03-31 | F25: An accreting liability plus penalties and interest, surfacing in the next diligence
A26: OI-02 | B26: Capitalized software stage review. Performed during this close for the first time. One project is carried at preliminary project stage and has been capitalized since June; another was charged for three months after it went live. Both are expense, not asset. | C26: Controller with VP Engineering | D26: 2026-02-28 | F26: R&D and cost of revenue both misstated, in opposite directions, and growing
A27: OI-03 | B27: Commission accelerator treatment. Q4-2025 accelerators are in the plan calculation and not in the accrual. No January P&L effect - commissions are capitalized under ASC 340-40 - but accrued commissions is understated and the cash goes out in February. | C27: Dir. RevOps with VP Finance | D27: 2026-02-20 | F27: The February payout exceeds the accrual and the difference lands as a variance nobody planned
A28: OI-04 | B28: Bonus attainment. FY2025 was accrued at 100% of target throughout. The compensation committee assessed a company multiplier on 22 January. The over-accrual is a prior-period item. | C28: Head of People with VP Finance | D28: 2026-02-15 | F28: FY2025 opex overstated and the FY2026 accrual starts from the wrong base
A29: OI-05 | B29: Intercompany FX. The ARC-UK balance was not revalued between September and January. Quantified at close. The revaluation policy is amended; the catch-up is a February entry. | C29: Controller | D29: 2026-02-20 | F29: An unrecorded movement that grows with sterling and eliminates to nil in USD while the exposure does not
A30: OI-11 | B30: Duplicate vendor invoice. USD 47,200 paid twice to Datadog for service period 2025-12, identified during this close. It relates to a closed period, so it is recorded and not adjusted. | C30: Accounting Manager | D30: 2026-02-28 | F30: Recovery gets harder the longer it sits, and the control that let it through is unchanged
A31: Cleared during this close, recorded here so the next reader can see the change
A32: Ref | B32: Item | C32: How it cleared
A33: OI-06 | B33: Bank reconciliation difference of USD 18,400, three months old | C33: Identified against bank advice MERC-FEB-01 as a real debit and written off. A difference persisting across three periods now escalates
A34: OI-07 | B34: Non-current deferred revenue. No amount had ever been classified as non-current | C34: The multi-year prepayment billed in December is reclassified in February; the split rule is now on the revenue recognition checklist
A35: OI-09 | B35: Renewal calendar. No contractual notice deadline, customer or vendor, was tracked anywhere | C35: Notice deadlines are now computed on both the customer agreement file and the software agreement file. The Gong renewal is what made the case
